<?xml version="1.0" ?>
<!-- =================================================================================== -->
<!-- |    This document was autogenerated by xacro from hx5_d20_right.xacro            | -->
<!-- |    EDITING THIS FILE BY HAND IS NOT RECOMMENDED                                 | -->
<!-- =================================================================================== -->
<robot name="hx5_d20_right">
  <link name="world"/>
  <joint name="world_fixed" type="fixed">
    <parent link="world"/>
    <child link="hx5_d20_right_base"/>
    <origin rpy="0 0 0" xyz="0 0 0"/>
  </joint>
  <link name="hx5_d20_right_base">
    <visual>
      <origin rpy="0 0 0" xyz="0 0 0"/>
      <geometry>
        <mesh filename="meshes/hx5_d20_rev2/hx5_d20_right/hx5_d20_base_unit.stl" scale="0.001 0.001 0.001"/>
      </geometry>
      <material name="grey">
        <color rgba="0.2 0.2 0.2 1"/>
      </material>
    </visual>
    <collision>
      <origin rpy="0 0 0" xyz="0 0 0"/>
      <geometry>
        <mesh filename="meshes/hx5_d20_rev2/hx5_d20_right/hx5_d20_base_unit.stl" scale="0.001 0.001 0.001"/>
      </geometry>
      <material name="grey">
        <color rgba="0.2 0.2 0.2 1"/>
      </material>
    </collision>
    <inertial>
      <origin xyz="-2.5954623e-03 1.7926275e-03 6.2957652e-02"/>
      <mass value="3.0185182e-01"/>
      <inertia ixx="5.4241294e-04" ixy="9.2340981e-06" ixz="-2.4709097e-06" iyy="3.8933294e-04" iyz="-1.6746740e-06" izz="2.1011567e-04"/>
    </inertial>
  </link>
  <!-- THUMB -->
  <joint name="finger_r_joint1" type="revolute">
    <parent link="hx5_d20_right_base"/>
    <child link="finger_r_link1"/>
    <origin rpy="0 0 0" xyz="-0.0125 0.03493 0.04475"/>
    <axis xyz="1 0 0"/>
    <limit effort="1000" lower="-1.57" upper="1.57" velocity="4.8"/>
    <dynamics damping="0.05"/>
  </joint>
  <link name="finger_r_link1">
    <visual>
      <origin rpy="0 0 0" xyz="0 0 0"/>
      <geometry>
        <mesh filename="meshes/hx5_d20_rev2/hx5_d20_right/hx5_d20_thumb_mcp.stl" scale="0.001 0.001 0.001"/>
      </geometry>
      <material name="grey">
        <color rgba="0.2 0.2 0.2 1"/>
      </material>
    </visual>
    <collision>
      <origin rpy="0 0 0" xyz="0 0 0"/>
      <geometry>
        <mesh filename="meshes/hx5_d20_rev2/hx5_d20_right/hx5_d20_thumb_mcp.stl" scale="0.001 0.001 0.001"/>
      </geometry>
      <material name="grey">
        <color rgba="0.2 0.2 0.2 1"/>
      </material>
    </collision>
    <inertial>
      <origin xyz="2.3807543e-02 1.3152378e-03 4.6035452e-04"/>
      <mass value="4.0868482e-02"/>
      <inertia ixx="2.8819304e-06" ixy="1.1855237e-06" ixz="4.4930159e-07" iyy="9.4333399e-06" iyz="-9.2023407e-08" izz="9.6512629e-06"/>
    </inertial>
  </link>
  <joint name="finger_r_joint2" type="revolute">
    <parent link="finger_r_link1"/>
    <child link="finger_r_link2"/>
    <origin rpy="0 0 0" xyz="0.039 0.0 0.0"/>
    <axis xyz="0 0 1"/>
    <limit effort="1000" lower="-3.14" upper="0.0" velocity="4.8"/>
    <dynamics damping="0.05"/>
  </joint>
  <link name="finger_r_link2">
    <visual>
      <origin rpy="0 0 0" xyz="0 0 0"/>
      <geometry>
        <mesh filename="meshes/hx5_d20_rev2/hx5_d20_right/hx5_d20_thumb_mcp2.stl" scale="0.001 0.001 0.001"/>
      </geometry>
      <material name="grey">
        <color rgba="0.2 0.2 0.2 1"/>
      </material>
    </visual>
    <collision>
      <origin rpy="0 0 0" xyz="0 0 0"/>
      <geometry>
        <mesh filename="meshes/hx5_d20_rev2/hx5_d20_right/hx5_d20_thumb_mcp2.stl" scale="0.001 0.001 0.001"/>
      </geometry>
      <material name="grey">
        <color rgba="0.2 0.2 0.2 1"/>
      </material>
    </collision>
    <inertial>
      <origin xyz="-3.5667920e-04 1.3999343e-02 3.5920711e-04"/>
      <mass value="1.1760611e-02"/>
      <inertia ixx="1.3023455e-06" ixy="5.3492870e-08" ixz="-1.5067505e-09" iyy="1.0556381e-06" iyz="5.3427868e-08" izz="1.3024709e-06"/>
    </inertial>
  </link>
  <joint name="finger_r_joint3" type="revolute">
    <parent link="finger_r_link2"/>
    <child link="finger_r_link3"/>
    <origin rpy="0 0 0" xyz="0.0 0.028 0.0"/>
    <axis xyz="1 0 0"/>
    <limit effort="1000" lower="0.0" upper="1.57" velocity="4.8"/>
    <dynamics damping="0.05"/>
  </joint>
  <link name="finger_r_link3">
    <visual>
      <origin rpy="0 0 0" xyz="0 0 0"/>
      <geometry>
        <mesh filename="meshes/hx5_d20_rev2/hx5_d20_right/hx5_d20_thumb_ip.stl" scale="0.001 0.001 0.001"/>
      </geometry>
      <material name="grey">
        <color rgba="0.2 0.2 0.2 1"/>
      </material>
    </visual>
    <collision>
      <origin rpy="0 0 0" xyz="0 0 0"/>
      <geometry>
        <mesh filename="meshes/hx5_d20_rev2/hx5_d20_right/hx5_d20_thumb_ip.stl" scale="0.001 0.001 0.001"/>
      </geometry>
      <material name="grey">
        <color rgba="0.2 0.2 0.2 1"/>
      </material>
    </collision>
    <inertial>
      <origin xyz="-1.0146203e-04 1.1343515e-02 4.0805550e-06"/>
      <mass value="3.4689700e-02"/>
      <inertia ixx="5.0370173e-06" ixy="1.1035638e-07" ixz="-5.4161055e-10" iyy="2.2580703e-06" iyz="8.5483839e-10" izz="5.4029785e-06"/>
    </inertial>
  </link>
  <joint name="finger_r_joint4" type="revolute">
    <parent link="finger_r_link3"/>
    <child link="finger_r_link4"/>
    <origin rpy="0 0 0" xyz="0.0 0.0355 0.0"/>
    <axis xyz="1 0 0"/>
    <limit effort="1000" lower="0.0" upper="1.57" velocity="4.8"/>
    <dynamics damping="0.05"/>
  </joint>
  <link name="finger_r_link4">
    <visual>
      <origin rpy="0 0 0" xyz="0 0 0"/>
      <geometry>
        <mesh filename="meshes/hx5_d20_rev2/hx5_d20_right/hx5_d20_thumb_tip.stl" scale="0.001 0.001 0.001"/>
      </geometry>
      <material name="grey">
        <color rgba="0.2 0.2 0.2 1"/>
      </material>
    </visual>
    <collision>
      <origin rpy="0 0 0" xyz="0 0 0"/>
      <geometry>
        <mesh filename="meshes/hx5_d20_rev2/hx5_d20_right/hx5_d20_thumb_tip.stl" scale="0.001 0.001 0.001"/>
      </geometry>
      <material name="grey">
        <color rgba="0.2 0.2 0.2 1"/>
      </material>
    </collision>
    <inertial>
      <origin xyz="6.6604979e-05 1.6824458e-02 2.2398502e-04"/>
      <mass value="4.3875236e-02"/>
      <inertia ixx="1.1160744e-05" ixy="-8.5593479e-09" ixz="-1.7171147e-09" iyy="2.8079428e-06" iyz="-3.0446511e-07" izz="1.1343106e-05"/>
    </inertial>
  </link>
  <joint name="finger_end_r_joint1" type="fixed">
    <parent link="finger_r_link4"/>
    <child link="finger_end_r_link1"/>
    <origin rpy="0 0 0" xyz="0.0 0.03975 0.0"/>
  </joint>
  <link name="finger_end_r_link1">
    <visual>
      <origin rpy="0 0 0" xyz="0 0 0"/>
      <geometry>
        <box size="0.01 0.01 0.01"/>
      </geometry>
      <material name="red">
        <color rgba="1.0 0.0 0.0 1"/>
      </material>
    </visual>
  </link>
  <!-- INDEX -->
  <joint name="finger_r_joint5" type="revolute">
    <parent link="hx5_d20_right_base"/>
    <child link="finger_r_link5"/>
    <origin rpy="0 0 0" xyz="-0.0015 0.03608 0.10275"/>
    <axis xyz="1 0 0"/>
    <limit effort="1000" lower="-0.6" upper="0.6" velocity="4.8"/>
    <dynamics damping="0.05"/>
  </joint>
  <link name="finger_r_link5">
    <visual>
      <origin rpy="0 0 0" xyz="0 0 0"/>
      <geometry>
        <mesh filename="meshes/hx5_d20_rev2/hx5_d20_right/hx5_d20_finger_mcp.stl" scale="0.001 0.001 0.001"/>
      </geometry>
      <material name="grey">
        <color rgba="0.2 0.2 0.2 1"/>
      </material>
    </visual>
    <collision>
      <origin rpy="0 0 0" xyz="0 0 0"/>
      <geometry>
        <mesh filename="meshes/hx5_d20_rev2/hx5_d20_right/hx5_d20_finger_mcp.stl" scale="0.001 0.001 0.001"/>
      </geometry>
      <material name="grey">
        <color rgba="0.2 0.2 0.2 1"/>
      </material>
    </collision>
    <inertial>
      <origin xyz="5.193401000e-03 -1.816308100e-05 2.111550700e-02"/>
      <mass value="3.880441100e-02"/>
      <inertia ixx="3.524993200e-06" ixy="1.364133900e-08" ixz="-3.766210300e-07" iyy="5.792157500e-06" iyz="1.153419900e-09" izz="4.712679800e-06"/>
    </inertial>
  </link>
  <joint name="finger_r_joint6" type="revolute">
    <parent link="finger_r_link5"/>
    <child link="finger_r_link6"/>
    <origin rpy="0 0 0" xyz="0.0165 0.0 0.0235"/>
    <axis xyz="0 1 0"/>
    <limit effort="1000" lower="0.0" upper="2.0" velocity="4.8"/>
    <dynamics damping="0.05"/>
  </joint>
  <link name="finger_r_link6">
    <visual>
      <origin rpy="0 0 0" xyz="0 0 0"/>
      <geometry>
        <mesh filename="meshes/hx5_d20_rev2/hx5_d20_right/hx5_d20_finger_pip.stl" scale="0.001 0.001 0.001"/>
      </geometry>
      <material name="grey">
        <color rgba="0.2 0.2 0.2 1"/>
      </material>
    </visual>
    <collision>
      <origin rpy="0 0 0" xyz="0 0 0"/>
      <geometry>
        <mesh filename="meshes/hx5_d20_rev2/hx5_d20_right/hx5_d20_finger_pip.stl" scale="0.001 0.001 0.001"/>
      </geometry>
      <material name="grey">
        <color rgba="0.2 0.2 0.2 1"/>
      </material>
    </collision>
    <inertial>
      <origin xyz="4.080555000e-06 1.014620300e-04 2.415648500e-02"/>
      <mass value="3.468970000e-02"/>
      <inertia ixx="5.402978500e-06" ixy="5.416105500e-10" ixz="-8.548383300e-10" iyy="5.037017300e-06" iyz="1.103563800e-07" izz="2.258070300e-06"/>
    </inertial>
  </link>
  <joint name="finger_r_joint7" type="revolute">
    <parent link="finger_r_link6"/>
    <child link="finger_r_link7"/>
    <origin rpy="0 0 0" xyz="0.0 0.0 0.0355"/>
    <axis xyz="0 1 0"/>
    <limit effort="1000" lower="0.0" upper="1.57" velocity="4.8"/>
    <dynamics damping="0.05"/>
  </joint>
  <link name="finger_r_link7">
    <visual>
      <origin rpy="0 0 0" xyz="0 0 0"/>
      <geometry>
        <mesh filename="meshes/hx5_d20_rev2/hx5_d20_right/hx5_d20_finger_dip.stl" scale="0.001 0.001 0.001"/>
      </geometry>
      <material name="grey">
        <color rgba="0.2 0.2 0.2 1"/>
      </material>
    </visual>
    <collision>
      <origin rpy="0 0 0" xyz="0 0 0"/>
      <geometry>
        <mesh filename="meshes/hx5_d20_rev2/hx5_d20_right/hx5_d20_finger_dip.stl" scale="0.001 0.001 0.001"/>
      </geometry>
      <material name="grey">
        <color rgba="0.2 0.2 0.2 1"/>
      </material>
    </collision>
    <inertial>
      <origin xyz="4.080555000e-06 1.014620300e-04 2.415648500e-02"/>
      <mass value="3.468970000e-02"/>
      <inertia ixx="5.402978500e-06" ixy="5.416105500e-10" ixz="-8.548383900e-10" iyy="5.037017300e-06" iyz="1.103563800e-07" izz="2.258070300e-06"/>
    </inertial>
  </link>
  <joint name="finger_r_joint8" type="revolute">
    <parent link="finger_r_link7"/>
    <child link="finger_r_link8"/>
    <origin rpy="0 0 0" xyz="0.0 0.0 0.0355"/>
    <axis xyz="0 1 0"/>
    <limit effort="1000" lower="0.0" upper="1.57" velocity="4.8"/>
    <dynamics damping="0.05"/>
  </joint>
  <link name="finger_r_link8">
    <visual>
      <origin rpy="0 0 0" xyz="0 0 0"/>
      <geometry>
        <mesh filename="meshes/hx5_d20_rev2/hx5_d20_right/hx5_d20_finger_tip.stl" scale="0.001 0.001 0.001"/>
      </geometry>
      <material name="grey">
        <color rgba="0.2 0.2 0.2 1"/>
      </material>
    </visual>
    <collision>
      <origin rpy="0 0 0" xyz="0 0 0"/>
      <geometry>
        <mesh filename="meshes/hx5_d20_rev2/hx5_d20_right/hx5_d20_finger_tip.stl" scale="0.001 0.001 0.001"/>
      </geometry>
      <material name="grey">
        <color rgba="0.2 0.2 0.2 1"/>
      </material>
    </collision>
    <inertial>
      <origin xyz="7.102508500e-04 4.723840800e-04 1.809864000e-02"/>
      <mass value="1.363720100e-02"/>
      <inertia ixx="2.232432600e-06" ixy="2.731013800e-09" ixz="-1.436237900e-07" iyy="2.018806500e-06" iyz="8.149987600e-08" izz="1.078660600e-06"/>
    </inertial>
  </link>
  <joint name="finger_end_r_joint2" type="fixed">
    <parent link="finger_r_link8"/>
    <child link="finger_end_r_link2"/>
    <origin rpy="0 0 0" xyz="0.0 0.0 0.02425"/>
  </joint>
  <link name="finger_end_r_link2">
    <visual>
      <origin rpy="0 0 0" xyz="0 0 0"/>
      <geometry>
        <box size="0.01 0.01 0.01"/>
      </geometry>
      <material name="red">
        <color rgba="1.0 0.0 0.0 1"/>
      </material>
    </visual>
  </link>
  <!-- MIDDLE -->
  <joint name="finger_r_joint9" type="revolute">
    <parent link="hx5_d20_right_base"/>
    <child link="finger_r_link9"/>
    <origin rpy="0 0 0" xyz="-0.0015 0.00908 0.11053"/>
    <axis xyz="1 0 0"/>
    <limit effort="1000" lower="-0.6" upper="0.6" velocity="4.8"/>
    <dynamics damping="0.05"/>
  </joint>
  <link name="finger_r_link9">
    <visual>
      <origin rpy="0 0 0" xyz="0 0 0"/>
      <geometry>
        <mesh filename="meshes/hx5_d20_rev2/hx5_d20_right/hx5_d20_finger_mcp.stl" scale="0.001 0.001 0.001"/>
      </geometry>
      <material name="grey">
        <color rgba="0.2 0.2 0.2 1"/>
      </material>
    </visual>
    <collision>
      <origin rpy="0 0 0" xyz="0 0 0"/>
      <geometry>
        <mesh filename="meshes/hx5_d20_rev2/hx5_d20_right/hx5_d20_finger_mcp.stl" scale="0.001 0.001 0.001"/>
      </geometry>
      <material name="grey">
        <color rgba="0.2 0.2 0.2 1"/>
      </material>
    </collision>
    <inertial>
      <origin xyz="5.193401000e-03 -1.816308100e-05 2.111550700e-02"/>
      <mass value="3.880441100e-02"/>
      <inertia ixx="3.524993200e-06" ixy="1.364133900e-08" ixz="-3.766210300e-07" iyy="5.792157500e-06" iyz="1.153419900e-09" izz="4.712679800e-06"/>
    </inertial>
  </link>
  <joint name="finger_r_joint10" type="revolute">
    <parent link="finger_r_link9"/>
    <child link="finger_r_link10"/>
    <origin rpy="0 0 0" xyz="0.0165 0.0 0.0235"/>
    <axis xyz="0 1 0"/>
    <limit effort="1000" lower="0.0" upper="2.0" velocity="4.8"/>
    <dynamics damping="0.05"/>
  </joint>
  <link name="finger_r_link10">
    <visual>
      <origin rpy="0 0 0" xyz="0 0 0"/>
      <geometry>
        <mesh filename="meshes/hx5_d20_rev2/hx5_d20_right/hx5_d20_finger_pip.stl" scale="0.001 0.001 0.001"/>
      </geometry>
      <material name="grey">
        <color rgba="0.2 0.2 0.2 1"/>
      </material>
    </visual>
    <collision>
      <origin rpy="0 0 0" xyz="0 0 0"/>
      <geometry>
        <mesh filename="meshes/hx5_d20_rev2/hx5_d20_right/hx5_d20_finger_pip.stl" scale="0.001 0.001 0.001"/>
      </geometry>
      <material name="grey">
        <color rgba="0.2 0.2 0.2 1"/>
      </material>
    </collision>
    <inertial>
      <origin xyz="4.080555000e-06 1.014620300e-04 2.415648500e-02"/>
      <mass value="3.468970000e-02"/>
      <inertia ixx="5.402978500e-06" ixy="5.416105500e-10" ixz="-8.548383300e-10" iyy="5.037017300e-06" iyz="1.103563800e-07" izz="2.258070300e-06"/>
    </inertial>
  </link>
  <joint name="finger_r_joint11" type="revolute">
    <parent link="finger_r_link10"/>
    <child link="finger_r_link11"/>
    <origin rpy="0 0 0" xyz="0.0 0.0 0.0355"/>
    <axis xyz="0 1 0"/>
    <limit effort="1000" lower="0.0" upper="1.57" velocity="4.8"/>
    <dynamics damping="0.05"/>
  </joint>
  <link name="finger_r_link11">
    <visual>
      <origin rpy="0 0 0" xyz="0 0 0"/>
      <geometry>
        <mesh filename="meshes/hx5_d20_rev2/hx5_d20_right/hx5_d20_finger_dip.stl" scale="0.001 0.001 0.001"/>
      </geometry>
      <material name="grey">
        <color rgba="0.2 0.2 0.2 1"/>
      </material>
    </visual>
    <collision>
      <origin rpy="0 0 0" xyz="0 0 0"/>
      <geometry>
        <mesh filename="meshes/hx5_d20_rev2/hx5_d20_right/hx5_d20_finger_dip.stl" scale="0.001 0.001 0.001"/>
      </geometry>
      <material name="grey">
        <color rgba="0.2 0.2 0.2 1"/>
      </material>
    </collision>
    <inertial>
      <origin xyz="4.080555000e-06 1.014620300e-04 2.415648500e-02"/>
      <mass value="3.468970000e-02"/>
      <inertia ixx="5.402978500e-06" ixy="5.416105500e-10" ixz="-8.548383900e-10" iyy="5.037017300e-06" iyz="1.103563800e-07" izz="2.258070300e-06"/>
    </inertial>
  </link>
  <joint name="finger_r_joint12" type="revolute">
    <parent link="finger_r_link11"/>
    <child link="finger_r_link12"/>
    <origin rpy="0 0 0" xyz="0.0 0.0 0.0355"/>
    <axis xyz="0 1 0"/>
    <limit effort="1000" lower="0.0" upper="1.57" velocity="4.8"/>
    <dynamics damping="0.05"/>
  </joint>
  <link name="finger_r_link12">
    <visual>
      <origin rpy="0 0 0" xyz="0 0 0"/>
      <geometry>
        <mesh filename="meshes/hx5_d20_rev2/hx5_d20_right/hx5_d20_finger_tip.stl" scale="0.001 0.001 0.001"/>
      </geometry>
      <material name="grey">
        <color rgba="0.2 0.2 0.2 1"/>
      </material>
    </visual>
    <collision>
      <origin rpy="0 0 0" xyz="0 0 0"/>
      <geometry>
        <mesh filename="meshes/hx5_d20_rev2/hx5_d20_right/hx5_d20_finger_tip.stl" scale="0.001 0.001 0.001"/>
      </geometry>
      <material name="grey">
        <color rgba="0.2 0.2 0.2 1"/>
      </material>
    </collision>
    <inertial>
      <origin xyz="7.102508500e-04 4.723840800e-04 1.809864000e-02"/>
      <mass value="1.363720100e-02"/>
      <inertia ixx="2.232432600e-06" ixy="2.731013800e-09" ixz="-1.436237900e-07" iyy="2.018806500e-06" iyz="8.149987600e-08" izz="1.078660600e-06"/>
    </inertial>
  </link>
  <joint name="finger_end_r_joint3" type="fixed">
    <parent link="finger_r_link12"/>
    <child link="finger_end_r_link3"/>
    <origin rpy="0 0 0" xyz="0.0 0.0 0.02425"/>
  </joint>
  <link name="finger_end_r_link3">
    <visual>
      <origin rpy="0 0 0" xyz="0 0 0"/>
      <geometry>
        <box size="0.01 0.01 0.01"/>
      </geometry>
      <material name="red">
        <color rgba="1.0 0.0 0.0 1"/>
      </material>
    </visual>
  </link>
  <!-- RING -->
  <joint name="finger_r_joint13" type="revolute">
    <parent link="hx5_d20_right_base"/>
    <child link="finger_r_link13"/>
    <origin rpy="0 0 0" xyz="-0.0015 -0.01792 0.10475"/>
    <axis xyz="1 0 0"/>
    <limit effort="1000" lower="-0.6" upper="0.6" velocity="4.8"/>
    <dynamics damping="0.05"/>
  </joint>
  <link name="finger_r_link13">
    <visual>
      <origin rpy="0 0 0" xyz="0 0 0"/>
      <geometry>
        <mesh filename="meshes/hx5_d20_rev2/hx5_d20_right/hx5_d20_finger_mcp.stl" scale="0.001 0.001 0.001"/>
      </geometry>
      <material name="grey">
        <color rgba="0.2 0.2 0.2 1"/>
      </material>
    </visual>
    <collision>
      <origin rpy="0 0 0" xyz="0 0 0"/>
      <geometry>
        <mesh filename="meshes/hx5_d20_rev2/hx5_d20_right/hx5_d20_finger_mcp.stl" scale="0.001 0.001 0.001"/>
      </geometry>
      <material name="grey">
        <color rgba="0.2 0.2 0.2 1"/>
      </material>
    </collision>
    <inertial>
      <origin xyz="5.193401000e-03 -1.816308100e-05 2.111550700e-02"/>
      <mass value="3.880441100e-02"/>
      <inertia ixx="3.524993200e-06" ixy="1.364133900e-08" ixz="-3.766210300e-07" iyy="5.792157500e-06" iyz="1.153419900e-09" izz="4.712679800e-06"/>
    </inertial>
  </link>
  <joint name="finger_r_joint14" type="revolute">
    <parent link="finger_r_link13"/>
    <child link="finger_r_link14"/>
    <origin rpy="0 0 0" xyz="0.0165 0.0 0.0235"/>
    <axis xyz="0 1 0"/>
    <limit effort="1000" lower="0.0" upper="2.0" velocity="4.8"/>
    <dynamics damping="0.05"/>
  </joint>
  <link name="finger_r_link14">
    <visual>
      <origin rpy="0 0 0" xyz="0 0 0"/>
      <geometry>
        <mesh filename="meshes/hx5_d20_rev2/hx5_d20_right/hx5_d20_finger_pip.stl" scale="0.001 0.001 0.001"/>
      </geometry>
      <material name="grey">
        <color rgba="0.2 0.2 0.2 1"/>
      </material>
    </visual>
    <collision>
      <origin rpy="0 0 0" xyz="0 0 0"/>
      <geometry>
        <mesh filename="meshes/hx5_d20_rev2/hx5_d20_right/hx5_d20_finger_pip.stl" scale="0.001 0.001 0.001"/>
      </geometry>
      <material name="grey">
        <color rgba="0.2 0.2 0.2 1"/>
      </material>
    </collision>
    <inertial>
      <origin xyz="4.080555000e-06 1.014620300e-04 2.415648500e-02"/>
      <mass value="3.468970000e-02"/>
      <inertia ixx="5.402978500e-06" ixy="5.416105500e-10" ixz="-8.548383300e-10" iyy="5.037017300e-06" iyz="1.103563800e-07" izz="2.258070300e-06"/>
    </inertial>
  </link>
  <joint name="finger_r_joint15" type="revolute">
    <parent link="finger_r_link14"/>
    <child link="finger_r_link15"/>
    <origin rpy="0 0 0" xyz="0.0 0.0 0.0355"/>
    <axis xyz="0 1 0"/>
    <limit effort="1000" lower="0.0" upper="1.57" velocity="4.8"/>
    <dynamics damping="0.05"/>
  </joint>
  <link name="finger_r_link15">
    <visual>
      <origin rpy="0 0 0" xyz="0 0 0"/>
      <geometry>
        <mesh filename="meshes/hx5_d20_rev2/hx5_d20_right/hx5_d20_finger_dip.stl" scale="0.001 0.001 0.001"/>
      </geometry>
      <material name="grey">
        <color rgba="0.2 0.2 0.2 1"/>
      </material>
    </visual>
    <collision>
      <origin rpy="0 0 0" xyz="0 0 0"/>
      <geometry>
        <mesh filename="meshes/hx5_d20_rev2/hx5_d20_right/hx5_d20_finger_dip.stl" scale="0.001 0.001 0.001"/>
      </geometry>
      <material name="grey">
        <color rgba="0.2 0.2 0.2 1"/>
      </material>
    </collision>
    <inertial>
      <origin xyz="4.080555000e-06 1.014620300e-04 2.415648500e-02"/>
      <mass value="3.468970000e-02"/>
      <inertia ixx="5.402978500e-06" ixy="5.416105500e-10" ixz="-8.548383900e-10" iyy="5.037017300e-06" iyz="1.103563800e-07" izz="2.258070300e-06"/>
    </inertial>
  </link>
  <joint name="finger_r_joint16" type="revolute">
    <parent link="finger_r_link15"/>
    <child link="finger_r_link16"/>
    <origin rpy="0 0 0" xyz="0.0 0.0 0.0355"/>
    <axis xyz="0 1 0"/>
    <limit effort="1000" lower="0.0" upper="1.57" velocity="4.8"/>
    <dynamics damping="0.05"/>
  </joint>
  <link name="finger_r_link16">
    <visual>
      <origin rpy="0 0 0" xyz="0 0 0"/>
      <geometry>
        <mesh filename="meshes/hx5_d20_rev2/hx5_d20_right/hx5_d20_finger_tip.stl" scale="0.001 0.001 0.001"/>
      </geometry>
      <material name="grey">
        <color rgba="0.2 0.2 0.2 1"/>
      </material>
    </visual>
    <collision>
      <origin rpy="0 0 0" xyz="0 0 0"/>
      <geometry>
        <mesh filename="meshes/hx5_d20_rev2/hx5_d20_right/hx5_d20_finger_tip.stl" scale="0.001 0.001 0.001"/>
      </geometry>
      <material name="grey">
        <color rgba="0.2 0.2 0.2 1"/>
      </material>
    </collision>
    <inertial>
      <origin xyz="7.102508500e-04 4.723840800e-04 1.809864000e-02"/>
      <mass value="1.363720100e-02"/>
      <inertia ixx="2.232432600e-06" ixy="2.731013800e-09" ixz="-1.436237900e-07" iyy="2.018806500e-06" iyz="8.149987600e-08" izz="1.078660600e-06"/>
    </inertial>
  </link>
  <joint name="finger_end_r_joint4" type="fixed">
    <parent link="finger_r_link16"/>
    <child link="finger_end_r_link4"/>
    <origin rpy="0 0 0" xyz="0.0 0.0 0.02425"/>
  </joint>
  <link name="finger_end_r_link4">
    <visual>
      <origin rpy="0 0 0" xyz="0 0 0"/>
      <geometry>
        <box size="0.01 0.01 0.01"/>
      </geometry>
      <material name="red">
        <color rgba="1.0 0.0 0.0 1"/>
      </material>
    </visual>
  </link>
  <!-- PINKY -->
  <joint name="finger_r_joint17" type="revolute">
    <parent link="hx5_d20_right_base"/>
    <child link="finger_r_link17"/>
    <origin rpy="0 0 0" xyz="-0.0015 -0.04492 0.08575"/>
    <axis xyz="1 0 0"/>
    <limit effort="1000" lower="-0.6" upper="0.6" velocity="4.8"/>
    <dynamics damping="0.05"/>
  </joint>
  <link name="finger_r_link17">
    <visual>
      <origin rpy="0 0 0" xyz="0 0 0"/>
      <geometry>
        <mesh filename="meshes/hx5_d20_rev2/hx5_d20_right/hx5_d20_finger_mcp.stl" scale="0.001 0.001 0.001"/>
      </geometry>
      <material name="grey">
        <color rgba="0.2 0.2 0.2 1"/>
      </material>
    </visual>
    <collision>
      <origin rpy="0 0 0" xyz="0 0 0"/>
      <geometry>
        <mesh filename="meshes/hx5_d20_rev2/hx5_d20_right/hx5_d20_finger_mcp.stl" scale="0.001 0.001 0.001"/>
      </geometry>
      <material name="grey">
        <color rgba="0.2 0.2 0.2 1"/>
      </material>
    </collision>
    <inertial>
      <origin xyz="5.193401000e-03 -1.816308100e-05 2.111550700e-02"/>
      <mass value="3.880441100e-02"/>
      <inertia ixx="3.524993200e-06" ixy="1.364133900e-08" ixz="-3.766210300e-07" iyy="5.792157500e-06" iyz="1.153419900e-09" izz="4.712679800e-06"/>
    </inertial>
  </link>
  <joint name="finger_r_joint18" type="revolute">
    <parent link="finger_r_link17"/>
    <child link="finger_r_link18"/>
    <origin rpy="0 0 0" xyz="0.0165 0.0 0.0235"/>
    <axis xyz="0 1 0"/>
    <limit effort="1000" lower="0.0" upper="2.0" velocity="4.8"/>
    <dynamics damping="0.05"/>
  </joint>
  <link name="finger_r_link18">
    <visual>
      <origin rpy="0 0 0" xyz="0 0 0"/>
      <geometry>
        <mesh filename="meshes/hx5_d20_rev2/hx5_d20_right/hx5_d20_finger_pip.stl" scale="0.001 0.001 0.001"/>
      </geometry>
      <material name="grey">
        <color rgba="0.2 0.2 0.2 1"/>
      </material>
    </visual>
    <collision>
      <origin rpy="0 0 0" xyz="0 0 0"/>
      <geometry>
        <mesh filename="meshes/hx5_d20_rev2/hx5_d20_right/hx5_d20_finger_pip.stl" scale="0.001 0.001 0.001"/>
      </geometry>
      <material name="grey">
        <color rgba="0.2 0.2 0.2 1"/>
      </material>
    </collision>
    <inertial>
      <origin xyz="4.080555000e-06 1.014620300e-04 2.415648500e-02"/>
      <mass value="3.468970000e-02"/>
      <inertia ixx="5.402978500e-06" ixy="5.416105500e-10" ixz="-8.548383300e-10" iyy="5.037017300e-06" iyz="1.103563800e-07" izz="2.258070300e-06"/>
    </inertial>
  </link>
  <joint name="finger_r_joint19" type="revolute">
    <parent link="finger_r_link18"/>
    <child link="finger_r_link19"/>
    <origin rpy="0 0 0" xyz="0.0 0.0 0.0355"/>
    <axis xyz="0 1 0"/>
    <limit effort="1000" lower="0.0" upper="1.57" velocity="4.8"/>
    <dynamics damping="0.05"/>
  </joint>
  <link name="finger_r_link19">
    <visual>
      <origin rpy="0 0 0" xyz="0 0 0"/>
      <geometry>
        <mesh filename="meshes/hx5_d20_rev2/hx5_d20_right/hx5_d20_finger_dip.stl" scale="0.001 0.001 0.001"/>
      </geometry>
      <material name="grey">
        <color rgba="0.2 0.2 0.2 1"/>
      </material>
    </visual>
    <collision>
      <origin rpy="0 0 0" xyz="0 0 0"/>
      <geometry>
        <mesh filename="meshes/hx5_d20_rev2/hx5_d20_right/hx5_d20_finger_dip.stl" scale="0.001 0.001 0.001"/>
      </geometry>
      <material name="grey">
        <color rgba="0.2 0.2 0.2 1"/>
      </material>
    </collision>
    <inertial>
      <origin xyz="4.080555000e-06 1.014620300e-04 2.415648500e-02"/>
      <mass value="3.468970000e-02"/>
      <inertia ixx="5.402978500e-06" ixy="5.416105500e-10" ixz="-8.548383900e-10" iyy="5.037017300e-06" iyz="1.103563800e-07" izz="2.258070300e-06"/>
    </inertial>
  </link>
  <joint name="finger_r_joint20" type="revolute">
    <parent link="finger_r_link19"/>
    <child link="finger_r_link20"/>
    <origin rpy="0 0 0" xyz="0.0 0.0 0.0355"/>
    <axis xyz="0 1 0"/>
    <limit effort="1000" lower="0.0" upper="1.57" velocity="4.8"/>
    <dynamics damping="0.05"/>
  </joint>
  <link name="finger_r_link20">
    <visual>
      <origin rpy="0 0 0" xyz="0 0 0"/>
      <geometry>
        <mesh filename="meshes/hx5_d20_rev2/hx5_d20_right/hx5_d20_finger_tip.stl" scale="0.001 0.001 0.001"/>
      </geometry>
      <material name="grey">
        <color rgba="0.2 0.2 0.2 1"/>
      </material>
    </visual>
    <collision>
      <origin rpy="0 0 0" xyz="0 0 0"/>
      <geometry>
        <mesh filename="meshes/hx5_d20_rev2/hx5_d20_right/hx5_d20_finger_tip.stl" scale="0.001 0.001 0.001"/>
      </geometry>
      <material name="grey">
        <color rgba="0.2 0.2 0.2 1"/>
      </material>
    </collision>
    <inertial>
      <origin xyz="7.102508500e-04 4.723840800e-04 1.809864000e-02"/>
      <mass value="1.363720100e-02"/>
      <inertia ixx="2.232432600e-06" ixy="2.731013800e-09" ixz="-1.436237900e-07" iyy="2.018806500e-06" iyz="8.149987600e-08" izz="1.078660600e-06"/>
    </inertial>
  </link>
  <joint name="finger_end_r_joint5" type="fixed">
    <parent link="finger_r_link20"/>
    <child link="finger_end_r_link5"/>
    <origin rpy="0 0 0" xyz="0.0 0.0 0.02425"/>
  </joint>
  <link name="finger_end_r_link5">
    <visual>
      <origin rpy="0 0 0" xyz="0 0 0"/>
      <geometry>
        <box size="0.01 0.01 0.01"/>
      </geometry>
      <material name="red">
        <color rgba="1.0 0.0 0.0 1"/>
      </material>
    </visual>
  </link>
  <gazebo reference="hx5_d20_right_base">
    <kp>1000000.0</kp>
    <kd>100.0</kd>
    <mu1>30.0</mu1>
    <mu2>30.0</mu2>
    <maxVel>1.0</maxVel>
    <minDepth>0.001</minDepth>
  </gazebo>
  <gazebo reference="finger_r_link1">
    <kp>1000000.0</kp>
    <kd>100.0</kd>
    <mu1>30.0</mu1>
    <mu2>30.0</mu2>
    <maxVel>1.0</maxVel>
    <minDepth>0.001</minDepth>
  </gazebo>
  <gazebo reference="finger_r_link2">
    <kp>1000000.0</kp>
    <kd>100.0</kd>
    <mu1>30.0</mu1>
    <mu2>30.0</mu2>
    <maxVel>1.0</maxVel>
    <minDepth>0.001</minDepth>
  </gazebo>
  <gazebo reference="finger_r_link3">
    <kp>1000000.0</kp>
    <kd>100.0</kd>
    <mu1>30.0</mu1>
    <mu2>30.0</mu2>
    <maxVel>1.0</maxVel>
    <minDepth>0.001</minDepth>
  </gazebo>
  <gazebo reference="finger_r_link4">
    <kp>1000000.0</kp>
    <kd>100.0</kd>
    <mu1>30.0</mu1>
    <mu2>30.0</mu2>
    <maxVel>1.0</maxVel>
    <minDepth>0.001</minDepth>
  </gazebo>
  <gazebo reference="finger_r_link5">
    <kp>1000000.0</kp>
    <kd>100.0</kd>
    <mu1>30.0</mu1>
    <mu2>30.0</mu2>
    <maxVel>1.0</maxVel>
    <minDepth>0.001</minDepth>
  </gazebo>
  <gazebo reference="finger_r_link6">
    <kp>1000000.0</kp>
    <kd>100.0</kd>
    <mu1>30.0</mu1>
    <mu2>30.0</mu2>
    <maxVel>1.0</maxVel>
    <minDepth>0.001</minDepth>
  </gazebo>
  <gazebo reference="finger_r_link7">
    <kp>1000000.0</kp>
    <kd>100.0</kd>
    <mu1>30.0</mu1>
    <mu2>30.0</mu2>
    <maxVel>1.0</maxVel>
    <minDepth>0.001</minDepth>
  </gazebo>
  <gazebo reference="finger_r_link8">
    <kp>1000000.0</kp>
    <kd>100.0</kd>
    <mu1>30.0</mu1>
    <mu2>30.0</mu2>
    <maxVel>1.0</maxVel>
    <minDepth>0.001</minDepth>
  </gazebo>
  <gazebo reference="finger_r_link9">
    <kp>1000000.0</kp>
    <kd>100.0</kd>
    <mu1>30.0</mu1>
    <mu2>30.0</mu2>
    <maxVel>1.0</maxVel>
    <minDepth>0.001</minDepth>
  </gazebo>
  <gazebo reference="finger_r_link10">
    <kp>1000000.0</kp>
    <kd>100.0</kd>
    <mu1>30.0</mu1>
    <mu2>30.0</mu2>
    <maxVel>1.0</maxVel>
    <minDepth>0.001</minDepth>
  </gazebo>
  <gazebo reference="finger_r_link11">
    <kp>1000000.0</kp>
    <kd>100.0</kd>
    <mu1>30.0</mu1>
    <mu2>30.0</mu2>
    <maxVel>1.0</maxVel>
    <minDepth>0.001</minDepth>
  </gazebo>
  <gazebo reference="finger_r_link12">
    <kp>1000000.0</kp>
    <kd>100.0</kd>
    <mu1>30.0</mu1>
    <mu2>30.0</mu2>
    <maxVel>1.0</maxVel>
    <minDepth>0.001</minDepth>
  </gazebo>
  <gazebo reference="finger_r_link13">
    <kp>1000000.0</kp>
    <kd>100.0</kd>
    <mu1>30.0</mu1>
    <mu2>30.0</mu2>
    <maxVel>1.0</maxVel>
    <minDepth>0.001</minDepth>
  </gazebo>
  <gazebo reference="finger_r_link14">
    <kp>1000000.0</kp>
    <kd>100.0</kd>
    <mu1>30.0</mu1>
    <mu2>30.0</mu2>
    <maxVel>1.0</maxVel>
    <minDepth>0.001</minDepth>
  </gazebo>
  <gazebo reference="finger_r_link15">
    <kp>1000000.0</kp>
    <kd>100.0</kd>
    <mu1>30.0</mu1>
    <mu2>30.0</mu2>
    <maxVel>1.0</maxVel>
    <minDepth>0.001</minDepth>
  </gazebo>
  <gazebo reference="finger_r_link16">
    <kp>1000000.0</kp>
    <kd>100.0</kd>
    <mu1>30.0</mu1>
    <mu2>30.0</mu2>
    <maxVel>1.0</maxVel>
    <minDepth>0.001</minDepth>
  </gazebo>
  <gazebo reference="finger_r_link17">
    <kp>1000000.0</kp>
    <kd>100.0</kd>
    <mu1>30.0</mu1>
    <mu2>30.0</mu2>
    <maxVel>1.0</maxVel>
    <minDepth>0.001</minDepth>
  </gazebo>
  <gazebo reference="finger_r_link18">
    <kp>1000000.0</kp>
    <kd>100.0</kd>
    <mu1>30.0</mu1>
    <mu2>30.0</mu2>
    <maxVel>1.0</maxVel>
    <minDepth>0.001</minDepth>
  </gazebo>
  <gazebo reference="finger_r_link19">
    <kp>1000000.0</kp>
    <kd>100.0</kd>
    <mu1>30.0</mu1>
    <mu2>30.0</mu2>
    <maxVel>1.0</maxVel>
    <minDepth>0.001</minDepth>
  </gazebo>
  <gazebo reference="finger_r_link20">
    <kp>1000000.0</kp>
    <kd>100.0</kd>
    <mu1>30.0</mu1>
    <mu2>30.0</mu2>
    <maxVel>1.0</maxVel>
    <minDepth>0.001</minDepth>
  </gazebo>
  <transmission name="hand_trans1">
    <type>transmission_interface/SimpleTransmission</type>
    <joint name="finger_r_joint1">
      <hardwareInterface>PositionJointInterface</hardwareInterface>
    </joint>
    <actuator name="hand_actuator1">
      <mechanicalReduction>1</mechanicalReduction>
      <hardwareInterface>PositionJointInterface</hardwareInterface>
    </actuator>
  </transmission>
  <transmission name="hand_trans2">
    <type>transmission_interface/SimpleTransmission</type>
    <joint name="finger_r_joint2">
      <hardwareInterface>PositionJointInterface</hardwareInterface>
    </joint>
    <actuator name="hand_actuator2">
      <mechanicalReduction>1</mechanicalReduction>
      <hardwareInterface>PositionJointInterface</hardwareInterface>
    </actuator>
  </transmission>
  <transmission name="hand_trans3">
    <type>transmission_interface/SimpleTransmission</type>
    <joint name="finger_r_joint3">
      <hardwareInterface>PositionJointInterface</hardwareInterface>
    </joint>
    <actuator name="hand_actuator3">
      <mechanicalReduction>1</mechanicalReduction>
      <hardwareInterface>PositionJointInterface</hardwareInterface>
    </actuator>
  </transmission>
  <transmission name="hand_trans4">
    <type>transmission_interface/SimpleTransmission</type>
    <joint name="finger_r_joint4">
      <hardwareInterface>PositionJointInterface</hardwareInterface>
    </joint>
    <actuator name="hand_actuator4">
      <mechanicalReduction>1</mechanicalReduction>
      <hardwareInterface>PositionJointInterface</hardwareInterface>
    </actuator>
  </transmission>
  <transmission name="hand_trans5">
    <type>transmission_interface/SimpleTransmission</type>
    <joint name="finger_r_joint5">
      <hardwareInterface>PositionJointInterface</hardwareInterface>
    </joint>
    <actuator name="hand_actuator5">
      <mechanicalReduction>1</mechanicalReduction>
      <hardwareInterface>PositionJointInterface</hardwareInterface>
    </actuator>
  </transmission>
  <transmission name="hand_trans6">
    <type>transmission_interface/SimpleTransmission</type>
    <joint name="finger_r_joint6">
      <hardwareInterface>PositionJointInterface</hardwareInterface>
    </joint>
    <actuator name="hand_actuator6">
      <mechanicalReduction>1</mechanicalReduction>
      <hardwareInterface>PositionJointInterface</hardwareInterface>
    </actuator>
  </transmission>
  <transmission name="hand_trans7">
    <type>transmission_interface/SimpleTransmission</type>
    <joint name="finger_r_joint7">
      <hardwareInterface>PositionJointInterface</hardwareInterface>
    </joint>
    <actuator name="hand_actuator7">
      <mechanicalReduction>1</mechanicalReduction>
      <hardwareInterface>PositionJointInterface</hardwareInterface>
    </actuator>
  </transmission>
  <transmission name="hand_trans8">
    <type>transmission_interface/SimpleTransmission</type>
    <joint name="finger_r_joint8">
      <hardwareInterface>PositionJointInterface</hardwareInterface>
    </joint>
    <actuator name="hand_actuator8">
      <mechanicalReduction>1</mechanicalReduction>
      <hardwareInterface>PositionJointInterface</hardwareInterface>
    </actuator>
  </transmission>
  <transmission name="hand_trans9">
    <type>transmission_interface/SimpleTransmission</type>
    <joint name="finger_r_joint9">
      <hardwareInterface>PositionJointInterface</hardwareInterface>
    </joint>
    <actuator name="hand_actuator9">
      <mechanicalReduction>1</mechanicalReduction>
      <hardwareInterface>PositionJointInterface</hardwareInterface>
    </actuator>
  </transmission>
  <transmission name="hand_trans10">
    <type>transmission_interface/SimpleTransmission</type>
    <joint name="finger_r_joint10">
      <hardwareInterface>PositionJointInterface</hardwareInterface>
    </joint>
    <actuator name="hand_actuator10">
      <mechanicalReduction>1</mechanicalReduction>
      <hardwareInterface>PositionJointInterface</hardwareInterface>
    </actuator>
  </transmission>
  <transmission name="hand_trans11">
    <type>transmission_interface/SimpleTransmission</type>
    <joint name="finger_r_joint11">
      <hardwareInterface>PositionJointInterface</hardwareInterface>
    </joint>
    <actuator name="hand_actuator11">
      <mechanicalReduction>1</mechanicalReduction>
      <hardwareInterface>PositionJointInterface</hardwareInterface>
    </actuator>
  </transmission>
  <transmission name="hand_trans12">
    <type>transmission_interface/SimpleTransmission</type>
    <joint name="finger_r_joint12">
      <hardwareInterface>PositionJointInterface</hardwareInterface>
    </joint>
    <actuator name="hand_actuator12">
      <mechanicalReduction>1</mechanicalReduction>
      <hardwareInterface>PositionJointInterface</hardwareInterface>
    </actuator>
  </transmission>
  <transmission name="hand_trans13">
    <type>transmission_interface/SimpleTransmission</type>
    <joint name="finger_r_joint13">
      <hardwareInterface>PositionJointInterface</hardwareInterface>
    </joint>
    <actuator name="hand_actuator13">
      <mechanicalReduction>1</mechanicalReduction>
      <hardwareInterface>PositionJointInterface</hardwareInterface>
    </actuator>
  </transmission>
  <transmission name="hand_trans14">
    <type>transmission_interface/SimpleTransmission</type>
    <joint name="finger_r_joint14">
      <hardwareInterface>PositionJointInterface</hardwareInterface>
    </joint>
    <actuator name="hand_actuator14">
      <mechanicalReduction>1</mechanicalReduction>
      <hardwareInterface>PositionJointInterface</hardwareInterface>
    </actuator>
  </transmission>
  <transmission name="hand_trans15">
    <type>transmission_interface/SimpleTransmission</type>
    <joint name="finger_r_joint15">
      <hardwareInterface>PositionJointInterface</hardwareInterface>
    </joint>
    <actuator name="hand_actuator15">
      <mechanicalReduction>1</mechanicalReduction>
      <hardwareInterface>PositionJointInterface</hardwareInterface>
    </actuator>
  </transmission>
  <transmission name="hand_trans16">
    <type>transmission_interface/SimpleTransmission</type>
    <joint name="finger_r_joint16">
      <hardwareInterface>PositionJointInterface</hardwareInterface>
    </joint>
    <actuator name="hand_actuator16">
      <mechanicalReduction>1</mechanicalReduction>
      <hardwareInterface>PositionJointInterface</hardwareInterface>
    </actuator>
  </transmission>
  <transmission name="hand_trans17">
    <type>transmission_interface/SimpleTransmission</type>
    <joint name="finger_r_joint17">
      <hardwareInterface>PositionJointInterface</hardwareInterface>
    </joint>
    <actuator name="hand_actuator17">
      <mechanicalReduction>1</mechanicalReduction>
      <hardwareInterface>PositionJointInterface</hardwareInterface>
    </actuator>
  </transmission>
  <transmission name="hand_trans18">
    <type>transmission_interface/SimpleTransmission</type>
    <joint name="finger_r_joint18">
      <hardwareInterface>PositionJointInterface</hardwareInterface>
    </joint>
    <actuator name="hand_actuator18">
      <mechanicalReduction>1</mechanicalReduction>
      <hardwareInterface>PositionJointInterface</hardwareInterface>
    </actuator>
  </transmission>
  <transmission name="hand_trans19">
    <type>transmission_interface/SimpleTransmission</type>
    <joint name="finger_r_joint19">
      <hardwareInterface>PositionJointInterface</hardwareInterface>
    </joint>
    <actuator name="hand_actuator19">
      <mechanicalReduction>1</mechanicalReduction>
      <hardwareInterface>PositionJointInterface</hardwareInterface>
    </actuator>
  </transmission>
  <transmission name="hand_trans20">
    <type>transmission_interface/SimpleTransmission</type>
    <joint name="finger_r_joint20">
      <hardwareInterface>PositionJointInterface</hardwareInterface>
    </joint>
    <actuator name="hand_actuator20">
      <mechanicalReduction>1</mechanicalReduction>
      <hardwareInterface>PositionJointInterface</hardwareInterface>
    </actuator>
  </transmission>
  <ros2_control is_async="true" name="RobotisHandSystem" type="system">
    <hardware>
      <plugin>dynamixel_hardware_interface/DynamixelHardware</plugin>
      <param name="port_name">/dev/ttyUSB0</param>
      <param name="baud_rate">4000000</param>
      <param name="error_timeout_ms">500</param>
      <param name="dynamixel_model_folder">/param/dxl_model</param>
      <param name="number_of_joints">20</param>
      <param name="number_of_transmissions">20</param>
      <param name="disable_torque_at_init">true</param>
      <param name="dynamixel_state_pub_msg_name">dynamixel_hardware_interface/dxl_state</param>
      <param name="get_dynamixel_data_srv_name">dynamixel_hardware_interface/get_dxl_data</param>
      <param name="set_dynamixel_data_srv_name">dynamixel_hardware_interface/set_dxl_data</param>
      <param name="reboot_dxl_srv_name">dynamixel_hardware_interface/reboot_dxl</param>
      <param name="set_dxl_torque_srv_name">dynamixel_hardware_interface/set_dxl_torque</param>
    </hardware>
    <joint name="finger_r_joint1">
      <command_interface name="position"/>
      <command_interface name="effort"/>
      <state_interface name="position"/>
      <state_interface name="velocity"/>
      <state_interface name="effort"/>
    </joint>
    <joint name="finger_r_joint2">
      <command_interface name="position"/>
      <command_interface name="effort"/>
      <state_interface name="position"/>
      <state_interface name="velocity"/>
      <state_interface name="effort"/>
    </joint>
    <joint name="finger_r_joint3">
      <command_interface name="position"/>
      <command_interface name="effort"/>
      <state_interface name="position"/>
      <state_interface name="velocity"/>
      <state_interface name="effort"/>
    </joint>
    <joint name="finger_r_joint4">
      <command_interface name="position"/>
      <command_interface name="effort"/>
      <state_interface name="position"/>
      <state_interface name="velocity"/>
      <state_interface name="effort"/>
    </joint>
    <sensor name="finger_r_sensor1">
      <state_interface name="Present Pressure 1"/>
      <state_interface name="Present Pressure 2"/>
      <state_interface name="Present Pressure 3"/>
      <state_interface name="Present Pressure 4"/>
      <state_interface name="Present Pressure 5"/>
      <state_interface name="Present Pressure 6"/>
      <state_interface name="Present Pressure 7"/>
      <state_interface name="Present Pressure 8"/>
      <state_interface name="Present Pressure 9"/>
    </sensor>
    <joint name="finger_r_joint5">
      <command_interface name="position"/>
      <command_interface name="effort"/>
      <state_interface name="position"/>
      <state_interface name="velocity"/>
      <state_interface name="effort"/>
    </joint>
    <joint name="finger_r_joint6">
      <command_interface name="position"/>
      <command_interface name="effort"/>
      <state_interface name="position"/>
      <state_interface name="velocity"/>
      <state_interface name="effort"/>
    </joint>
    <joint name="finger_r_joint7">
      <command_interface name="position"/>
      <command_interface name="effort"/>
      <state_interface name="position"/>
      <state_interface name="velocity"/>
      <state_interface name="effort"/>
    </joint>
    <joint name="finger_r_joint8">
      <command_interface name="position"/>
      <command_interface name="effort"/>
      <state_interface name="position"/>
      <state_interface name="velocity"/>
      <state_interface name="effort"/>
    </joint>
    <sensor name="finger_r_sensor2">
      <state_interface name="Present Pressure 1"/>
      <state_interface name="Present Pressure 2"/>
      <state_interface name="Present Pressure 3"/>
      <state_interface name="Present Pressure 4"/>
      <state_interface name="Present Pressure 5"/>
      <state_interface name="Present Pressure 6"/>
      <state_interface name="Present Pressure 7"/>
      <state_interface name="Present Pressure 8"/>
      <state_interface name="Present Pressure 9"/>
    </sensor>
    <joint name="finger_r_joint9">
      <command_interface name="position"/>
      <command_interface name="effort"/>
      <state_interface name="position"/>
      <state_interface name="velocity"/>
      <state_interface name="effort"/>
    </joint>
    <joint name="finger_r_joint10">
      <command_interface name="position"/>
      <command_interface name="effort"/>
      <state_interface name="position"/>
      <state_interface name="velocity"/>
      <state_interface name="effort"/>
    </joint>
    <joint name="finger_r_joint11">
      <command_interface name="position"/>
      <command_interface name="effort"/>
      <state_interface name="position"/>
      <state_interface name="velocity"/>
      <state_interface name="effort"/>
    </joint>
    <joint name="finger_r_joint12">
      <command_interface name="position"/>
      <command_interface name="effort"/>
      <state_interface name="position"/>
      <state_interface name="velocity"/>
      <state_interface name="effort"/>
    </joint>
    <sensor name="finger_r_sensor3">
      <state_interface name="Present Pressure 1"/>
      <state_interface name="Present Pressure 2"/>
      <state_interface name="Present Pressure 3"/>
      <state_interface name="Present Pressure 4"/>
      <state_interface name="Present Pressure 5"/>
      <state_interface name="Present Pressure 6"/>
      <state_interface name="Present Pressure 7"/>
      <state_interface name="Present Pressure 8"/>
      <state_interface name="Present Pressure 9"/>
    </sensor>
    <joint name="finger_r_joint13">
      <command_interface name="position"/>
      <command_interface name="effort"/>
      <state_interface name="position"/>
      <state_interface name="velocity"/>
      <state_interface name="effort"/>
    </joint>
    <joint name="finger_r_joint14">
      <command_interface name="position"/>
      <command_interface name="effort"/>
      <state_interface name="position"/>
      <state_interface name="velocity"/>
      <state_interface name="effort"/>
    </joint>
    <joint name="finger_r_joint15">
      <command_interface name="position"/>
      <command_interface name="effort"/>
      <state_interface name="position"/>
      <state_interface name="velocity"/>
      <state_interface name="effort"/>
    </joint>
    <joint name="finger_r_joint16">
      <command_interface name="position"/>
      <command_interface name="effort"/>
      <state_interface name="position"/>
      <state_interface name="velocity"/>
      <state_interface name="effort"/>
    </joint>
    <sensor name="finger_r_sensor4">
      <state_interface name="Present Pressure 1"/>
      <state_interface name="Present Pressure 2"/>
      <state_interface name="Present Pressure 3"/>
      <state_interface name="Present Pressure 4"/>
      <state_interface name="Present Pressure 5"/>
      <state_interface name="Present Pressure 6"/>
      <state_interface name="Present Pressure 7"/>
      <state_interface name="Present Pressure 8"/>
      <state_interface name="Present Pressure 9"/>
    </sensor>
    <joint name="finger_r_joint17">
      <command_interface name="position"/>
      <command_interface name="effort"/>
      <state_interface name="position"/>
      <state_interface name="velocity"/>
      <state_interface name="effort"/>
    </joint>
    <joint name="finger_r_joint18">
      <command_interface name="position"/>
      <command_interface name="effort"/>
      <state_interface name="position"/>
      <state_interface name="velocity"/>
      <state_interface name="effort"/>
    </joint>
    <joint name="finger_r_joint19">
      <command_interface name="position"/>
      <command_interface name="effort"/>
      <state_interface name="position"/>
      <state_interface name="velocity"/>
      <state_interface name="effort"/>
    </joint>
    <joint name="finger_r_joint20">
      <command_interface name="position"/>
      <command_interface name="effort"/>
      <state_interface name="position"/>
      <state_interface name="velocity"/>
      <state_interface name="effort"/>
    </joint>
    <sensor name="finger_r_sensor5">
      <state_interface name="Present Pressure 1"/>
      <state_interface name="Present Pressure 2"/>
      <state_interface name="Present Pressure 3"/>
      <state_interface name="Present Pressure 4"/>
      <state_interface name="Present Pressure 5"/>
      <state_interface name="Present Pressure 6"/>
      <state_interface name="Present Pressure 7"/>
      <state_interface name="Present Pressure 8"/>
      <state_interface name="Present Pressure 9"/>
    </sensor>
    <gpio name="hand_r_controller">
      <param name="type">controller</param>
      <param name="ID">110</param>
      <param name="Reboot">1</param>
      <param name="Table Sync Enable">0</param>
      <param name="Bus Watchdog">100</param>
      <param name="SyncTable 1 ID 1">111</param>
      <param name="SyncTable 1 ID 2">112</param>
      <param name="SyncTable 1 ID 3">113</param>
      <param name="SyncTable 1 ID 4">114</param>
      <param name="SyncTable 1 ID 5">115</param>
      <param name="SyncTable 2 ID 1">116</param>
      <param name="SyncTable 2 ID 2">117</param>
      <param name="SyncTable 2 ID 3">118</param>
      <param name="SyncTable 2 ID 4">119</param>
      <param name="SyncTable 2 ID 5">120</param>
      <param name="SyncTable 3 ID 1">121</param>
      <param name="SyncTable 3 ID 2">122</param>
      <param name="SyncTable 3 ID 3">123</param>
      <param name="SyncTable 3 ID 4">124</param>
      <param name="SyncTable 3 ID 5">125</param>
      <param name="SyncTable 4 ID 1">126</param>
      <param name="SyncTable 4 ID 2">127</param>
      <param name="SyncTable 4 ID 3">128</param>
      <param name="SyncTable 4 ID 4">129</param>
      <param name="SyncTable 4 ID 5">130</param>
      <param name="SyncTable 5 ID 1">131</param>
      <param name="SyncTable 5 ID 2">132</param>
      <param name="SyncTable 5 ID 3">133</param>
      <param name="SyncTable 5 ID 4">134</param>
      <param name="SyncTable 5 ID 5">135</param>
      <param name="SyncTable 1 Read Address 1">224</param>
      <param name="SyncTable 1 Read Address 2">224</param>
      <param name="SyncTable 1 Read Address 3">224</param>
      <param name="SyncTable 1 Read Address 4">224</param>
      <param name="SyncTable 1 Read Address 5">72</param>
      <param name="SyncTable 1 Read Size 1">6</param>
      <param name="SyncTable 1 Read Size 2">6</param>
      <param name="SyncTable 1 Read Size 3">6</param>
      <param name="SyncTable 1 Read Size 4">6</param>
      <param name="SyncTable 1 Read Size 5">9</param>
      <param name="SyncTable 1 Write Address 1">230</param>
      <param name="SyncTable 1 Write Address 2">230</param>
      <param name="SyncTable 1 Write Address 3">230</param>
      <param name="SyncTable 1 Write Address 4">230</param>
      <param name="SyncTable 1 Write Address 5">0</param>
      <param name="SyncTable 1 Write Size 1">4</param>
      <param name="SyncTable 1 Write Size 2">4</param>
      <param name="SyncTable 1 Write Size 3">4</param>
      <param name="SyncTable 1 Write Size 4">4</param>
      <param name="SyncTable 1 Write Size 5">0</param>
      <param name="SyncTable 2 Read Address 1">224</param>
      <param name="SyncTable 2 Read Address 2">224</param>
      <param name="SyncTable 2 Read Address 3">224</param>
      <param name="SyncTable 2 Read Address 4">224</param>
      <param name="SyncTable 2 Read Address 5">72</param>
      <param name="SyncTable 2 Read Size 1">6</param>
      <param name="SyncTable 2 Read Size 2">6</param>
      <param name="SyncTable 2 Read Size 3">6</param>
      <param name="SyncTable 2 Read Size 4">6</param>
      <param name="SyncTable 2 Read Size 5">9</param>
      <param name="SyncTable 2 Write Address 1">230</param>
      <param name="SyncTable 2 Write Address 2">230</param>
      <param name="SyncTable 2 Write Address 3">230</param>
      <param name="SyncTable 2 Write Address 4">230</param>
      <param name="SyncTable 2 Write Address 5">0</param>
      <param name="SyncTable 2 Write Size 1">4</param>
      <param name="SyncTable 2 Write Size 2">4</param>
      <param name="SyncTable 2 Write Size 3">4</param>
      <param name="SyncTable 2 Write Size 4">4</param>
      <param name="SyncTable 2 Write Size 5">0</param>
      <param name="SyncTable 3 Read Address 1">224</param>
      <param name="SyncTable 3 Read Address 2">224</param>
      <param name="SyncTable 3 Read Address 3">224</param>
      <param name="SyncTable 3 Read Address 4">224</param>
      <param name="SyncTable 3 Read Address 5">72</param>
      <param name="SyncTable 3 Read Size 1">6</param>
      <param name="SyncTable 3 Read Size 2">6</param>
      <param name="SyncTable 3 Read Size 3">6</param>
      <param name="SyncTable 3 Read Size 4">6</param>
      <param name="SyncTable 3 Read Size 5">9</param>
      <param name="SyncTable 3 Write Address 1">230</param>
      <param name="SyncTable 3 Write Address 2">230</param>
      <param name="SyncTable 3 Write Address 3">230</param>
      <param name="SyncTable 3 Write Address 4">230</param>
      <param name="SyncTable 3 Write Address 5">0</param>
      <param name="SyncTable 3 Write Size 1">4</param>
      <param name="SyncTable 3 Write Size 2">4</param>
      <param name="SyncTable 3 Write Size 3">4</param>
      <param name="SyncTable 3 Write Size 4">4</param>
      <param name="SyncTable 3 Write Size 5">0</param>
      <param name="SyncTable 4 Read Address 1">224</param>
      <param name="SyncTable 4 Read Address 2">224</param>
      <param name="SyncTable 4 Read Address 3">224</param>
      <param name="SyncTable 4 Read Address 4">224</param>
      <param name="SyncTable 4 Read Address 5">72</param>
      <param name="SyncTable 4 Read Size 1">6</param>
      <param name="SyncTable 4 Read Size 2">6</param>
      <param name="SyncTable 4 Read Size 3">6</param>
      <param name="SyncTable 4 Read Size 4">6</param>
      <param name="SyncTable 4 Read Size 5">9</param>
      <param name="SyncTable 4 Write Address 1">230</param>
      <param name="SyncTable 4 Write Address 2">230</param>
      <param name="SyncTable 4 Write Address 3">230</param>
      <param name="SyncTable 4 Write Address 4">230</param>
      <param name="SyncTable 4 Write Address 5">0</param>
      <param name="SyncTable 4 Write Size 1">4</param>
      <param name="SyncTable 4 Write Size 2">4</param>
      <param name="SyncTable 4 Write Size 3">4</param>
      <param name="SyncTable 4 Write Size 4">4</param>
      <param name="SyncTable 4 Write Size 5">0</param>
      <param name="SyncTable 5 Read Address 1">224</param>
      <param name="SyncTable 5 Read Address 2">224</param>
      <param name="SyncTable 5 Read Address 3">224</param>
      <param name="SyncTable 5 Read Address 4">224</param>
      <param name="SyncTable 5 Read Address 5">72</param>
      <param name="SyncTable 5 Read Size 1">6</param>
      <param name="SyncTable 5 Read Size 2">6</param>
      <param name="SyncTable 5 Read Size 3">6</param>
      <param name="SyncTable 5 Read Size 4">6</param>
      <param name="SyncTable 5 Read Size 5">9</param>
      <param name="SyncTable 5 Write Address 1">230</param>
      <param name="SyncTable 5 Write Address 2">230</param>
      <param name="SyncTable 5 Write Address 3">230</param>
      <param name="SyncTable 5 Write Address 4">230</param>
      <param name="SyncTable 5 Write Address 5">0</param>
      <param name="SyncTable 5 Write Size 1">4</param>
      <param name="SyncTable 5 Write Size 2">4</param>
      <param name="SyncTable 5 Write Size 3">4</param>
      <param name="SyncTable 5 Write Size 4">4</param>
      <param name="SyncTable 5 Write Size 5">0</param>
    </gpio>
    <gpio name="dxl111_init">
      <param name="type">controller</param>
      <param name="ID">111</param>
      <param name="Reboot">1</param>
      <param name="Startup Configuration">2</param>
      <param name="Operating Mode">5</param>
      <param name="Drive Mode">13</param>
      <param name="Bus Watchdog">100</param>
      <param name="Profile Velocity">100</param>
      <param name="Profile Acceleration">50</param>
      <param name="Position P Gain">500</param>
      <param name="Position D Gain">1000</param>
      <param name="Homing Offset">0</param>
      <param name="Indirect Address 1">126</param>
      <param name="Indirect Address 2">127</param>
      <param name="Indirect Address 3">128</param>
      <param name="Indirect Address 4">129</param>
      <param name="Indirect Address 5">132</param>
      <param name="Indirect Address 6">133</param>
      <param name="Indirect Address 7">102</param>
      <param name="Indirect Address 8">103</param>
      <param name="Indirect Address 9">116</param>
      <param name="Indirect Address 10">117</param>
    </gpio>
    <gpio name="dxl112_init">
      <param name="type">controller</param>
      <param name="ID">112</param>
      <param name="Reboot">1</param>
      <param name="Startup Configuration">2</param>
      <param name="Operating Mode">5</param>
      <param name="Drive Mode">12</param>
      <param name="Bus Watchdog">100</param>
      <param name="Profile Velocity">100</param>
      <param name="Profile Acceleration">50</param>
      <param name="Position P Gain">500</param>
      <param name="Position D Gain">1000</param>
      <param name="Homing Offset">-1024</param>
      <param name="Indirect Address 1">126</param>
      <param name="Indirect Address 2">127</param>
      <param name="Indirect Address 3">128</param>
      <param name="Indirect Address 4">129</param>
      <param name="Indirect Address 5">132</param>
      <param name="Indirect Address 6">133</param>
      <param name="Indirect Address 7">102</param>
      <param name="Indirect Address 8">103</param>
      <param name="Indirect Address 9">116</param>
      <param name="Indirect Address 10">117</param>
    </gpio>
    <gpio name="dxl113_init">
      <param name="type">controller</param>
      <param name="ID">113</param>
      <param name="Reboot">1</param>
      <param name="Startup Configuration">2</param>
      <param name="Operating Mode">5</param>
      <param name="Drive Mode">12</param>
      <param name="Bus Watchdog">100</param>
      <param name="Profile Velocity">100</param>
      <param name="Profile Acceleration">50</param>
      <param name="Position P Gain">500</param>
      <param name="Position D Gain">1000</param>
      <param name="Indirect Address 1">126</param>
      <param name="Indirect Address 2">127</param>
      <param name="Indirect Address 3">128</param>
      <param name="Indirect Address 4">129</param>
      <param name="Indirect Address 5">132</param>
      <param name="Indirect Address 6">133</param>
      <param name="Indirect Address 7">102</param>
      <param name="Indirect Address 8">103</param>
      <param name="Indirect Address 9">116</param>
      <param name="Indirect Address 10">117</param>
    </gpio>
    <gpio name="dxl114_init">
      <param name="type">controller</param>
      <param name="ID">114</param>
      <param name="Reboot">1</param>
      <param name="Startup Configuration">2</param>
      <param name="Operating Mode">5</param>
      <param name="Drive Mode">12</param>
      <param name="Bus Watchdog">100</param>
      <param name="Profile Velocity">100</param>
      <param name="Profile Acceleration">50</param>
      <param name="Position P Gain">500</param>
      <param name="Position D Gain">1000</param>
      <param name="Indirect Address 1">126</param>
      <param name="Indirect Address 2">127</param>
      <param name="Indirect Address 3">128</param>
      <param name="Indirect Address 4">129</param>
      <param name="Indirect Address 5">132</param>
      <param name="Indirect Address 6">133</param>
      <param name="Indirect Address 7">102</param>
      <param name="Indirect Address 8">103</param>
      <param name="Indirect Address 9">116</param>
      <param name="Indirect Address 10">117</param>
    </gpio>
    <gpio name="dxl116_init">
      <param name="type">controller</param>
      <param name="ID">116</param>
      <param name="Reboot">1</param>
      <param name="Startup Configuration">2</param>
      <param name="Operating Mode">5</param>
      <param name="Drive Mode">12</param>
      <param name="Bus Watchdog">100</param>
      <param name="Profile Velocity">100</param>
      <param name="Profile Acceleration">50</param>
      <param name="Position P Gain">500</param>
      <param name="Position D Gain">1000</param>
      <param name="Indirect Address 1">126</param>
      <param name="Indirect Address 2">127</param>
      <param name="Indirect Address 3">128</param>
      <param name="Indirect Address 4">129</param>
      <param name="Indirect Address 5">132</param>
      <param name="Indirect Address 6">133</param>
      <param name="Indirect Address 7">102</param>
      <param name="Indirect Address 8">103</param>
      <param name="Indirect Address 9">116</param>
      <param name="Indirect Address 10">117</param>
    </gpio>
    <gpio name="dxl117_init">
      <param name="type">controller</param>
      <param name="ID">117</param>
      <param name="Reboot">1</param>
      <param name="Startup Configuration">2</param>
      <param name="Operating Mode">5</param>
      <param name="Drive Mode">12</param>
      <param name="Bus Watchdog">100</param>
      <param name="Profile Velocity">100</param>
      <param name="Profile Acceleration">50</param>
      <param name="Position P Gain">500</param>
      <param name="Position D Gain">1000</param>
      <param name="Homing Offset">1024</param>
      <param name="Indirect Address 1">126</param>
      <param name="Indirect Address 2">127</param>
      <param name="Indirect Address 3">128</param>
      <param name="Indirect Address 4">129</param>
      <param name="Indirect Address 5">132</param>
      <param name="Indirect Address 6">133</param>
      <param name="Indirect Address 7">102</param>
      <param name="Indirect Address 8">103</param>
      <param name="Indirect Address 9">116</param>
      <param name="Indirect Address 10">117</param>
    </gpio>
    <gpio name="dxl118_init">
      <param name="type">controller</param>
      <param name="ID">118</param>
      <param name="Reboot">1</param>
      <param name="Startup Configuration">2</param>
      <param name="Operating Mode">5</param>
      <param name="Drive Mode">12</param>
      <param name="Bus Watchdog">100</param>
      <param name="Profile Velocity">100</param>
      <param name="Profile Acceleration">50</param>
      <param name="Position P Gain">500</param>
      <param name="Position D Gain">1000</param>
      <param name="Indirect Address 1">126</param>
      <param name="Indirect Address 2">127</param>
      <param name="Indirect Address 3">128</param>
      <param name="Indirect Address 4">129</param>
      <param name="Indirect Address 5">132</param>
      <param name="Indirect Address 6">133</param>
      <param name="Indirect Address 7">102</param>
      <param name="Indirect Address 8">103</param>
      <param name="Indirect Address 9">116</param>
      <param name="Indirect Address 10">117</param>
    </gpio>
    <gpio name="dxl119_init">
      <param name="type">controller</param>
      <param name="ID">119</param>
      <param name="Reboot">1</param>
      <param name="Startup Configuration">2</param>
      <param name="Operating Mode">5</param>
      <param name="Drive Mode">12</param>
      <param name="Bus Watchdog">100</param>
      <param name="Profile Velocity">100</param>
      <param name="Profile Acceleration">50</param>
      <param name="Position P Gain">500</param>
      <param name="Position D Gain">1000</param>
      <param name="Indirect Address 1">126</param>
      <param name="Indirect Address 2">127</param>
      <param name="Indirect Address 3">128</param>
      <param name="Indirect Address 4">129</param>
      <param name="Indirect Address 5">132</param>
      <param name="Indirect Address 6">133</param>
      <param name="Indirect Address 7">102</param>
      <param name="Indirect Address 8">103</param>
      <param name="Indirect Address 9">116</param>
      <param name="Indirect Address 10">117</param>
    </gpio>
    <gpio name="dxl121_init">
      <param name="type">controller</param>
      <param name="ID">121</param>
      <param name="Reboot">1</param>
      <param name="Startup Configuration">2</param>
      <param name="Operating Mode">5</param>
      <param name="Drive Mode">12</param>
      <param name="Bus Watchdog">100</param>
      <param name="Profile Velocity">100</param>
      <param name="Profile Acceleration">50</param>
      <param name="Position P Gain">500</param>
      <param name="Position D Gain">1000</param>
      <param name="Homing Offset">171</param>
      <param name="Indirect Address 1">126</param>
      <param name="Indirect Address 2">127</param>
      <param name="Indirect Address 3">128</param>
      <param name="Indirect Address 4">129</param>
      <param name="Indirect Address 5">132</param>
      <param name="Indirect Address 6">133</param>
      <param name="Indirect Address 7">102</param>
      <param name="Indirect Address 8">103</param>
      <param name="Indirect Address 9">116</param>
      <param name="Indirect Address 10">117</param>
    </gpio>
    <gpio name="dxl122_init">
      <param name="type">controller</param>
      <param name="ID">122</param>
      <param name="Reboot">1</param>
      <param name="Startup Configuration">2</param>
      <param name="Operating Mode">5</param>
      <param name="Drive Mode">12</param>
      <param name="Bus Watchdog">100</param>
      <param name="Profile Velocity">100</param>
      <param name="Profile Acceleration">50</param>
      <param name="Position P Gain">500</param>
      <param name="Position D Gain">1000</param>
      <param name="Homing Offset">1024</param>
      <param name="Indirect Address 1">126</param>
      <param name="Indirect Address 2">127</param>
      <param name="Indirect Address 3">128</param>
      <param name="Indirect Address 4">129</param>
      <param name="Indirect Address 5">132</param>
      <param name="Indirect Address 6">133</param>
      <param name="Indirect Address 7">102</param>
      <param name="Indirect Address 8">103</param>
      <param name="Indirect Address 9">116</param>
      <param name="Indirect Address 10">117</param>
    </gpio>
    <gpio name="dxl123_init">
      <param name="type">controller</param>
      <param name="ID">123</param>
      <param name="Reboot">1</param>
      <param name="Startup Configuration">2</param>
      <param name="Operating Mode">5</param>
      <param name="Drive Mode">12</param>
      <param name="Bus Watchdog">100</param>
      <param name="Profile Velocity">100</param>
      <param name="Profile Acceleration">50</param>
      <param name="Position P Gain">500</param>
      <param name="Position D Gain">1000</param>
      <param name="Indirect Address 1">126</param>
      <param name="Indirect Address 2">127</param>
      <param name="Indirect Address 3">128</param>
      <param name="Indirect Address 4">129</param>
      <param name="Indirect Address 5">132</param>
      <param name="Indirect Address 6">133</param>
      <param name="Indirect Address 7">102</param>
      <param name="Indirect Address 8">103</param>
      <param name="Indirect Address 9">116</param>
      <param name="Indirect Address 10">117</param>
    </gpio>
    <gpio name="dxl124_init">
      <param name="type">controller</param>
      <param name="ID">124</param>
      <param name="Reboot">1</param>
      <param name="Startup Configuration">2</param>
      <param name="Operating Mode">5</param>
      <param name="Drive Mode">12</param>
      <param name="Bus Watchdog">100</param>
      <param name="Profile Velocity">100</param>
      <param name="Profile Acceleration">50</param>
      <param name="Position P Gain">500</param>
      <param name="Position D Gain">1000</param>
      <param name="Indirect Address 1">126</param>
      <param name="Indirect Address 2">127</param>
      <param name="Indirect Address 3">128</param>
      <param name="Indirect Address 4">129</param>
      <param name="Indirect Address 5">132</param>
      <param name="Indirect Address 6">133</param>
      <param name="Indirect Address 7">102</param>
      <param name="Indirect Address 8">103</param>
      <param name="Indirect Address 9">116</param>
      <param name="Indirect Address 10">117</param>
    </gpio>
    <gpio name="dxl126_init">
      <param name="type">controller</param>
      <param name="ID">126</param>
      <param name="Reboot">1</param>
      <param name="Startup Configuration">2</param>
      <param name="Operating Mode">5</param>
      <param name="Drive Mode">12</param>
      <param name="Bus Watchdog">100</param>
      <param name="Profile Velocity">100</param>
      <param name="Profile Acceleration">50</param>
      <param name="Position P Gain">500</param>
      <param name="Position D Gain">1000</param>
      <param name="Homing Offset">341</param>
      <param name="Indirect Address 1">126</param>
      <param name="Indirect Address 2">127</param>
      <param name="Indirect Address 3">128</param>
      <param name="Indirect Address 4">129</param>
      <param name="Indirect Address 5">132</param>
      <param name="Indirect Address 6">133</param>
      <param name="Indirect Address 7">102</param>
      <param name="Indirect Address 8">103</param>
      <param name="Indirect Address 9">116</param>
      <param name="Indirect Address 10">117</param>
    </gpio>
    <gpio name="dxl127_init">
      <param name="type">controller</param>
      <param name="ID">127</param>
      <param name="Reboot">1</param>
      <param name="Startup Configuration">2</param>
      <param name="Operating Mode">5</param>
      <param name="Drive Mode">12</param>
      <param name="Bus Watchdog">100</param>
      <param name="Profile Velocity">100</param>
      <param name="Profile Acceleration">50</param>
      <param name="Position P Gain">500</param>
      <param name="Position D Gain">1000</param>
      <param name="Homing Offset">1024</param>
      <param name="Indirect Address 1">126</param>
      <param name="Indirect Address 2">127</param>
      <param name="Indirect Address 3">128</param>
      <param name="Indirect Address 4">129</param>
      <param name="Indirect Address 5">132</param>
      <param name="Indirect Address 6">133</param>
      <param name="Indirect Address 7">102</param>
      <param name="Indirect Address 8">103</param>
      <param name="Indirect Address 9">116</param>
      <param name="Indirect Address 10">117</param>
    </gpio>
    <gpio name="dxl128_init">
      <param name="type">controller</param>
      <param name="ID">128</param>
      <param name="Reboot">1</param>
      <param name="Startup Configuration">2</param>
      <param name="Operating Mode">5</param>
      <param name="Drive Mode">12</param>
      <param name="Bus Watchdog">100</param>
      <param name="Profile Velocity">100</param>
      <param name="Profile Acceleration">50</param>
      <param name="Position P Gain">500</param>
      <param name="Position D Gain">1000</param>
      <param name="Indirect Address 1">126</param>
      <param name="Indirect Address 2">127</param>
      <param name="Indirect Address 3">128</param>
      <param name="Indirect Address 4">129</param>
      <param name="Indirect Address 5">132</param>
      <param name="Indirect Address 6">133</param>
      <param name="Indirect Address 7">102</param>
      <param name="Indirect Address 8">103</param>
      <param name="Indirect Address 9">116</param>
      <param name="Indirect Address 10">117</param>
    </gpio>
    <gpio name="dxl129_init">
      <param name="type">controller</param>
      <param name="ID">129</param>
      <param name="Reboot">1</param>
      <param name="Startup Configuration">2</param>
      <param name="Operating Mode">5</param>
      <param name="Drive Mode">12</param>
      <param name="Bus Watchdog">100</param>
      <param name="Profile Velocity">100</param>
      <param name="Profile Acceleration">50</param>
      <param name="Position P Gain">500</param>
      <param name="Position D Gain">1000</param>
      <param name="Indirect Address 1">126</param>
      <param name="Indirect Address 2">127</param>
      <param name="Indirect Address 3">128</param>
      <param name="Indirect Address 4">129</param>
      <param name="Indirect Address 5">132</param>
      <param name="Indirect Address 6">133</param>
      <param name="Indirect Address 7">102</param>
      <param name="Indirect Address 8">103</param>
      <param name="Indirect Address 9">116</param>
      <param name="Indirect Address 10">117</param>
    </gpio>
    <gpio name="dxl131_init">
      <param name="type">controller</param>
      <param name="ID">131</param>
      <param name="Reboot">1</param>
      <param name="Startup Configuration">2</param>
      <param name="Operating Mode">5</param>
      <param name="Drive Mode">12</param>
      <param name="Bus Watchdog">100</param>
      <param name="Profile Velocity">100</param>
      <param name="Profile Acceleration">50</param>
      <param name="Position P Gain">500</param>
      <param name="Position D Gain">1000</param>
      <param name="Homing Offset">682</param>
      <param name="Indirect Address 1">126</param>
      <param name="Indirect Address 2">127</param>
      <param name="Indirect Address 3">128</param>
      <param name="Indirect Address 4">129</param>
      <param name="Indirect Address 5">132</param>
      <param name="Indirect Address 6">133</param>
      <param name="Indirect Address 7">102</param>
      <param name="Indirect Address 8">103</param>
      <param name="Indirect Address 9">116</param>
      <param name="Indirect Address 10">117</param>
    </gpio>
    <gpio name="dxl132_init">
      <param name="type">controller</param>
      <param name="ID">132</param>
      <param name="Reboot">1</param>
      <param name="Startup Configuration">2</param>
      <param name="Operating Mode">5</param>
      <param name="Drive Mode">12</param>
      <param name="Bus Watchdog">100</param>
      <param name="Profile Velocity">100</param>
      <param name="Profile Acceleration">50</param>
      <param name="Position P Gain">500</param>
      <param name="Position D Gain">1000</param>
      <param name="Homing Offset">1024</param>
      <param name="Indirect Address 1">126</param>
      <param name="Indirect Address 2">127</param>
      <param name="Indirect Address 3">128</param>
      <param name="Indirect Address 4">129</param>
      <param name="Indirect Address 5">132</param>
      <param name="Indirect Address 6">133</param>
      <param name="Indirect Address 7">102</param>
      <param name="Indirect Address 8">103</param>
      <param name="Indirect Address 9">116</param>
      <param name="Indirect Address 10">117</param>
    </gpio>
    <gpio name="dxl133_init">
      <param name="type">controller</param>
      <param name="ID">133</param>
      <param name="Reboot">1</param>
      <param name="Startup Configuration">2</param>
      <param name="Operating Mode">5</param>
      <param name="Drive Mode">12</param>
      <param name="Bus Watchdog">100</param>
      <param name="Profile Velocity">100</param>
      <param name="Profile Acceleration">50</param>
      <param name="Position P Gain">500</param>
      <param name="Position D Gain">1000</param>
      <param name="Indirect Address 1">126</param>
      <param name="Indirect Address 2">127</param>
      <param name="Indirect Address 3">128</param>
      <param name="Indirect Address 4">129</param>
      <param name="Indirect Address 5">132</param>
      <param name="Indirect Address 6">133</param>
      <param name="Indirect Address 7">102</param>
      <param name="Indirect Address 8">103</param>
      <param name="Indirect Address 9">116</param>
      <param name="Indirect Address 10">117</param>
    </gpio>
    <gpio name="dxl134_init">
      <param name="type">controller</param>
      <param name="ID">134</param>
      <param name="Reboot">1</param>
      <param name="Startup Configuration">2</param>
      <param name="Operating Mode">5</param>
      <param name="Drive Mode">12</param>
      <param name="Bus Watchdog">100</param>
      <param name="Profile Velocity">100</param>
      <param name="Profile Acceleration">50</param>
      <param name="Position P Gain">500</param>
      <param name="Position D Gain">1000</param>
      <param name="Indirect Address 1">126</param>
      <param name="Indirect Address 2">127</param>
      <param name="Indirect Address 3">128</param>
      <param name="Indirect Address 4">129</param>
      <param name="Indirect Address 5">132</param>
      <param name="Indirect Address 6">133</param>
      <param name="Indirect Address 7">102</param>
      <param name="Indirect Address 8">103</param>
      <param name="Indirect Address 9">116</param>
      <param name="Indirect Address 10">117</param>
    </gpio>
    <gpio name="hand_r_controller_dummy">
      <param name="type">controller</param>
      <param name="ID">110</param>
      <param name="Table Sync Enable">1</param>
    </gpio>
    <gpio name="dxl111">
      <command_interface name="Goal Position"/>
      <command_interface name="Goal Current"/>
      <state_interface name="Present Position"/>
      <state_interface name="Present Velocity"/>
      <state_interface name="Present Current"/>
      <param name="type">virtual_dxl</param>
      <param name="ID">111</param>
      <param name="comm_id">110</param>
      <param name="model_num">6001</param>
    </gpio>
    <gpio name="dxl112">
      <command_interface name="Goal Position"/>
      <command_interface name="Goal Current"/>
      <state_interface name="Present Position"/>
      <state_interface name="Present Velocity"/>
      <state_interface name="Present Current"/>
      <param name="type">virtual_dxl</param>
      <param name="ID">112</param>
      <param name="comm_id">110</param>
      <param name="model_num">6002</param>
    </gpio>
    <gpio name="dxl113">
      <command_interface name="Goal Position"/>
      <command_interface name="Goal Current"/>
      <state_interface name="Present Position"/>
      <state_interface name="Present Velocity"/>
      <state_interface name="Present Current"/>
      <param name="type">virtual_dxl</param>
      <param name="ID">113</param>
      <param name="comm_id">110</param>
      <param name="model_num">6003</param>
    </gpio>
    <gpio name="dxl114">
      <command_interface name="Goal Position"/>
      <command_interface name="Goal Current"/>
      <state_interface name="Present Position"/>
      <state_interface name="Present Velocity"/>
      <state_interface name="Present Current"/>
      <param name="type">virtual_dxl</param>
      <param name="ID">114</param>
      <param name="comm_id">110</param>
      <param name="model_num">6004</param>
    </gpio>
    <gpio name="finger_r_sensor1">
      <state_interface name="Present Pressure 1"/>
      <state_interface name="Present Pressure 2"/>
      <state_interface name="Present Pressure 3"/>
      <state_interface name="Present Pressure 4"/>
      <state_interface name="Present Pressure 5"/>
      <state_interface name="Present Pressure 6"/>
      <state_interface name="Present Pressure 7"/>
      <state_interface name="Present Pressure 8"/>
      <state_interface name="Present Pressure 9"/>
      <param name="type">virtual_sensor</param>
      <param name="ID">115</param>
      <param name="comm_id">110</param>
      <param name="model_num">6005</param>
    </gpio>
    <gpio name="dxl116">
      <command_interface name="Goal Position"/>
      <command_interface name="Goal Current"/>
      <state_interface name="Present Position"/>
      <state_interface name="Present Velocity"/>
      <state_interface name="Present Current"/>
      <param name="type">virtual_dxl</param>
      <param name="ID">116</param>
      <param name="comm_id">110</param>
      <param name="model_num">6006</param>
    </gpio>
    <gpio name="dxl117">
      <command_interface name="Goal Position"/>
      <command_interface name="Goal Current"/>
      <state_interface name="Present Position"/>
      <state_interface name="Present Velocity"/>
      <state_interface name="Present Current"/>
      <param name="type">virtual_dxl</param>
      <param name="ID">117</param>
      <param name="comm_id">110</param>
      <param name="model_num">6007</param>
    </gpio>
    <gpio name="dxl118">
      <command_interface name="Goal Position"/>
      <command_interface name="Goal Current"/>
      <state_interface name="Present Position"/>
      <state_interface name="Present Velocity"/>
      <state_interface name="Present Current"/>
      <param name="type">virtual_dxl</param>
      <param name="ID">118</param>
      <param name="comm_id">110</param>
      <param name="model_num">6008</param>
    </gpio>
    <gpio name="dxl119">
      <command_interface name="Goal Position"/>
      <command_interface name="Goal Current"/>
      <state_interface name="Present Position"/>
      <state_interface name="Present Velocity"/>
      <state_interface name="Present Current"/>
      <param name="type">virtual_dxl</param>
      <param name="ID">119</param>
      <param name="comm_id">110</param>
      <param name="model_num">6009</param>
    </gpio>
    <gpio name="finger_r_sensor2">
      <state_interface name="Present Pressure 1"/>
      <state_interface name="Present Pressure 2"/>
      <state_interface name="Present Pressure 3"/>
      <state_interface name="Present Pressure 4"/>
      <state_interface name="Present Pressure 5"/>
      <state_interface name="Present Pressure 6"/>
      <state_interface name="Present Pressure 7"/>
      <state_interface name="Present Pressure 8"/>
      <state_interface name="Present Pressure 9"/>
      <param name="type">virtual_sensor</param>
      <param name="ID">120</param>
      <param name="comm_id">110</param>
      <param name="model_num">6010</param>
    </gpio>
    <gpio name="dxl121">
      <command_interface name="Goal Position"/>
      <command_interface name="Goal Current"/>
      <state_interface name="Present Position"/>
      <state_interface name="Present Velocity"/>
      <state_interface name="Present Current"/>
      <param name="type">virtual_dxl</param>
      <param name="ID">121</param>
      <param name="comm_id">110</param>
      <param name="model_num">6011</param>
    </gpio>
    <gpio name="dxl122">
      <command_interface name="Goal Position"/>
      <command_interface name="Goal Current"/>
      <state_interface name="Present Position"/>
      <state_interface name="Present Velocity"/>
      <state_interface name="Present Current"/>
      <param name="type">virtual_dxl</param>
      <param name="ID">122</param>
      <param name="comm_id">110</param>
      <param name="model_num">6012</param>
    </gpio>
    <gpio name="dxl123">
      <command_interface name="Goal Position"/>
      <command_interface name="Goal Current"/>
      <state_interface name="Present Position"/>
      <state_interface name="Present Velocity"/>
      <state_interface name="Present Current"/>
      <param name="type">virtual_dxl</param>
      <param name="ID">123</param>
      <param name="comm_id">110</param>
      <param name="model_num">6013</param>
    </gpio>
    <gpio name="dxl124">
      <command_interface name="Goal Position"/>
      <command_interface name="Goal Current"/>
      <state_interface name="Present Position"/>
      <state_interface name="Present Velocity"/>
      <state_interface name="Present Current"/>
      <param name="type">virtual_dxl</param>
      <param name="ID">124</param>
      <param name="comm_id">110</param>
      <param name="model_num">6014</param>
    </gpio>
    <gpio name="finger_r_sensor3">
      <state_interface name="Present Pressure 1"/>
      <state_interface name="Present Pressure 2"/>
      <state_interface name="Present Pressure 3"/>
      <state_interface name="Present Pressure 4"/>
      <state_interface name="Present Pressure 5"/>
      <state_interface name="Present Pressure 6"/>
      <state_interface name="Present Pressure 7"/>
      <state_interface name="Present Pressure 8"/>
      <state_interface name="Present Pressure 9"/>
      <param name="type">virtual_sensor</param>
      <param name="ID">125</param>
      <param name="comm_id">110</param>
      <param name="model_num">6015</param>
    </gpio>
    <gpio name="dxl126">
      <command_interface name="Goal Position"/>
      <command_interface name="Goal Current"/>
      <state_interface name="Present Position"/>
      <state_interface name="Present Velocity"/>
      <state_interface name="Present Current"/>
      <param name="type">virtual_dxl</param>
      <param name="ID">126</param>
      <param name="comm_id">110</param>
      <param name="model_num">6016</param>
    </gpio>
    <gpio name="dxl127">
      <command_interface name="Goal Position"/>
      <command_interface name="Goal Current"/>
      <state_interface name="Present Position"/>
      <state_interface name="Present Velocity"/>
      <state_interface name="Present Current"/>
      <param name="type">virtual_dxl</param>
      <param name="ID">127</param>
      <param name="comm_id">110</param>
      <param name="model_num">6017</param>
    </gpio>
    <gpio name="dxl128">
      <command_interface name="Goal Position"/>
      <command_interface name="Goal Current"/>
      <state_interface name="Present Position"/>
      <state_interface name="Present Velocity"/>
      <state_interface name="Present Current"/>
      <param name="type">virtual_dxl</param>
      <param name="ID">128</param>
      <param name="comm_id">110</param>
      <param name="model_num">6018</param>
    </gpio>
    <gpio name="dxl129">
      <command_interface name="Goal Position"/>
      <command_interface name="Goal Current"/>
      <state_interface name="Present Position"/>
      <state_interface name="Present Velocity"/>
      <state_interface name="Present Current"/>
      <param name="type">virtual_dxl</param>
      <param name="ID">129</param>
      <param name="comm_id">110</param>
      <param name="model_num">6019</param>
    </gpio>
    <gpio name="finger_r_sensor4">
      <state_interface name="Present Pressure 1"/>
      <state_interface name="Present Pressure 2"/>
      <state_interface name="Present Pressure 3"/>
      <state_interface name="Present Pressure 4"/>
      <state_interface name="Present Pressure 5"/>
      <state_interface name="Present Pressure 6"/>
      <state_interface name="Present Pressure 7"/>
      <state_interface name="Present Pressure 8"/>
      <state_interface name="Present Pressure 9"/>
      <param name="type">virtual_sensor</param>
      <param name="ID">130</param>
      <param name="comm_id">110</param>
      <param name="model_num">6020</param>
    </gpio>
    <gpio name="dxl131">
      <command_interface name="Goal Position"/>
      <command_interface name="Goal Current"/>
      <state_interface name="Present Position"/>
      <state_interface name="Present Velocity"/>
      <state_interface name="Present Current"/>
      <param name="type">virtual_dxl</param>
      <param name="ID">131</param>
      <param name="comm_id">110</param>
      <param name="model_num">6021</param>
    </gpio>
    <gpio name="dxl132">
      <command_interface name="Goal Position"/>
      <command_interface name="Goal Current"/>
      <state_interface name="Present Position"/>
      <state_interface name="Present Velocity"/>
      <state_interface name="Present Current"/>
      <param name="type">virtual_dxl</param>
      <param name="ID">132</param>
      <param name="comm_id">110</param>
      <param name="model_num">6022</param>
    </gpio>
    <gpio name="dxl133">
      <command_interface name="Goal Position"/>
      <command_interface name="Goal Current"/>
      <state_interface name="Present Position"/>
      <state_interface name="Present Velocity"/>
      <state_interface name="Present Current"/>
      <param name="type">virtual_dxl</param>
      <param name="ID">133</param>
      <param name="comm_id">110</param>
      <param name="model_num">6023</param>
    </gpio>
    <gpio name="dxl134">
      <command_interface name="Goal Position"/>
      <command_interface name="Goal Current"/>
      <state_interface name="Present Position"/>
      <state_interface name="Present Velocity"/>
      <state_interface name="Present Current"/>
      <param name="type">virtual_dxl</param>
      <param name="ID">134</param>
      <param name="comm_id">110</param>
      <param name="model_num">6024</param>
    </gpio>
    <gpio name="finger_r_sensor5">
      <state_interface name="Present Pressure 1"/>
      <state_interface name="Present Pressure 2"/>
      <state_interface name="Present Pressure 3"/>
      <state_interface name="Present Pressure 4"/>
      <state_interface name="Present Pressure 5"/>
      <state_interface name="Present Pressure 6"/>
      <state_interface name="Present Pressure 7"/>
      <state_interface name="Present Pressure 8"/>
      <state_interface name="Present Pressure 9"/>
      <param name="type">virtual_sensor</param>
      <param name="ID">135</param>
      <param name="comm_id">110</param>
      <param name="model_num">6025</param>
    </gpio>
  </ros2_control>
  <gazebo>
    <plugin filename="gz_ros2_control-system" name="gz_ros2_control::GazeboSimROS2ControlPlugin">
      <parameters>/root/ros2_ws/install/robotis_hand_bringup/share/robotis_hand_bringup/config/robotis_hand_hardware_controller_manager.yaml</parameters>
    </plugin>
  </gazebo>
</robot>
